Workbook

Sheet 工作表1
A1: 序号 | B1: 企业微信群名称 | C1: 运营公司 | D1: 项目点代码 | E1: 项目点名称 | F1: 备注 | G1: 是否加群-张利拉 | H1: IT是否配置完成-邓虎 | I1: 群ID
A2: 1 | B2: 德立安～太子湾逸菲下单群 | C2: 深圳市德立安食品有限公司 | D2: BIZ20240710105439 | E2: 深圳市裕顺达酒店管理有限公司 | G2: OK-0625 | H2: OK | I2: ==_xlfn.XLOOKUP(B2,工作表2!A:A,工作表2!B:B) -> wrigAJEAAADTfUfEE9mk0HLoKlK_PSfw
A3: 2 | B3: 商旅-武林之星项目业务对接群 | C3: 浙江/丰厨(上海)供应链管理有限公司 | D3: KHXMD1152 | E3: 商旅-干调 | F3: 一个群多个项目点下单 | G3: OK-0625 | H3: OK-0701 | I3: ==_xlfn.XLOOKUP(B3,工作表2!A:A,工作表2!B:B) -> wrigAJEAAA6WrJotbzMQ1SlwWqkoWykg
A4: 3 | B4: 商旅-武林之星项目业务对接群 | C4: 浙江/丰厨(上海)供应链管理有限公司 | D4: KHXMD1076 | E4: 杭州商旅进出口贸易有限公司 | F4: 一个群多个项目点下单 | G4: OK-0625 | H4: OK-0701 | I4: ==_xlfn.XLOOKUP(B4,工作表2!A:A,工作表2!B:B) -> wrigAJEAAA6WrJotbzMQ1SlwWqkoWykg
A5: 4 | B5: 海谯汇-益海嘉里（丰厨） | C5: 浙江/丰厨(上海)供应链管理有限公司 | D5: KHXMD4918 | E5: 亳州海谯汇后勤管理服务有限公司 | G5: OK-0625 | H5: OK | I5: ==_xlfn.XLOOKUP(B5,工作表2!A:A,工作表2!B:B) -> wrigAJEAAAbgyZq1soc1RQFfTj-hKASg
A6: 5 | B6: 益海深度合作推进群 | C6: 浙江/丰厨(上海)供应链管理有限公司 | D6: KHXMD9425 | E6: 浙江智汇配送有限公司利辛分公司 | G6: OK-0625 | H6: OK | I6: ==_xlfn.XLOOKUP(B6,工作表2!A:A,工作表2!B:B) -> wrigAJEAAAouZAnW_S8Ep_O8DHKzadDA
A7: 6 | B7: 杭州工厂-丰厨供应链业务对接群 | C7: 浙江/丰厨(上海)供应链管理有限公司 | D7: KHXMD0941 | E7: ZH-SP-ZLAQZN 益嘉工业-工厂食堂 | G7: OK-0625 | H7: OK | I7: ==_xlfn.XLOOKUP(B7,工作表2!A:A,工作表2!B:B) -> wrigAJEAAAVSKtIQLmQz6mPCgLHHiFFw
A8: 7 | B8: 杭州央厨-供应链业务对接群 | C8: 浙江/丰厨(上海)供应链管理有限公司 | D8: KHXMD2477 | E8: 益嘉丰厨-干调 | F8: 一个群多个项目点下单 | G8: OK-0625 | H8: OK-0701 | I8: ==_xlfn.XLOOKUP(B8,工作表2!A:A,工作表2!B:B) -> wrigAJEAAAmwtbpxOuj9iCIeu2tq4vEA
A9: 8 | B9: 杭州央厨-供应链业务对接群 | C9: 浙江/丰厨(上海)供应链管理有限公司 | D9: KHXMD1565 | E9: 杭州央厨-冻品 | F9: 一个群多个项目点下单 | G9: OK-0625 | H9: OK-0701 | I9: ==_xlfn.XLOOKUP(B9,工作表2!A:A,工作表2!B:B) -> wrigAJEAAAmwtbpxOuj9iCIeu2tq4vEA
A10: 9 | B10: 杭州央厨-供应链业务对接群 | C10: 浙江/丰厨(上海)供应链管理有限公司 | D10: KHXMD0243 | E10: 益嘉丰厨（杭州）食品有限公司 | F10: 一个群多个项目点下单 | G10: OK-0625 | H10: OK-0701 | I10: ==_xlfn.XLOOKUP(B10,工作表2!A:A,工作表2!B:B) -> wrigAJEAAAmwtbpxOuj9iCIeu2tq4vEA
A11: 10 | B11: 益分销PLUS-深圳国际会展中心洲际酒店 | C11: 深圳市德立安食品有限公司 | D11: BIZ20230510111217 | E11: 深圳市招华国际会展发展有限公司深圳国际会展中心洲际酒店 -会展湾中港广场6栋A座 | G11: OK-0625 | H11: OK | I11: ==_xlfn.XLOOKUP(B11,工作表2!A:A,工作表2!B:B) -> wrigAJEAAAFuEvg1ObWhcmy2q_M6Wq3g
A12: 11 | B12: 德立安-辉胜阁订单群 | C12: 深圳市德立安食品有限公司 | D12: BIZ20240814142654 | E12: 深圳市中航城置业发展有限公司辉盛阁国际公寓分公司 | G12: OK-0625 | H12: OK | I12: ==_xlfn.XLOOKUP(B12,工作表2!A:A,工作表2!B:B) -> wrigAJEAAATmrWPjznHCmzprmkomUE6Q
A13: 12 | B13: 德立安-富悦订单群 | C13: 深圳市德立安食品有限公司 | D13: BIZ20250605134442 | E13: 富悦(深圳)酒店管理有限公司 | G13: OK-0625 | H13: OK | I13: ==_xlfn.XLOOKUP(B13,工作表2!A:A,工作表2!B:B) -> wrigAJEAAA36ZXYMgR51AmStwcCel6qA
A14: 13 | B14: 德立安-温德姆酒店下单群 | C14: 益海嘉里德立安(陕西)食品有限公司 | D14: BIZ20240511112021 | E14: 西安豪享来投资控股有限公司豪享来温德姆至尊酒店 | G14: OK-0625 | H14: OK | I14: ==_xlfn.XLOOKUP(B14,工作表2!A:A,工作表2!B:B) -> wrigAJEAAAXnRYN0xEAjkHJNDM7rVfyA
A15: 14 | B15: 德立安-悦来下单群 | C15: 益海嘉里德立安(陕西)食品有限公司 | D15: BIZ20230506163709 | E15: 西安悦来酒店管理有限公司曲江新区分公司 | G15: OK-0625 | H15: OK | I15: ==_xlfn.XLOOKUP(B15,工作表2!A:A,工作表2!B:B) -> wrigAJEAAA0lzFlH6VPwiKciUNqEMvOA
A16: 15 | B16: 冀三姐下单群 | C16: 西安/丰厨(上海)供应链管理有限公司 | D16: KHXMD1819 | E16: 益海-大寨路天悦店 | F16: 一个群多个项目点下单 | G16: OK-0625 | H16: OK-0701 | I16: ==_xlfn.XLOOKUP(B16,工作表2!A:A,工作表2!B:B) -> wrigAJEAAAEtJGi9pK0AJyh92DOGwpJw
A17: 16 | B17: 冀三姐下单群 | C17: 西安/丰厨(上海)供应链管理有限公司 | D17: KHXMD1820 | E17: 益海-财富中心店 | F17: 一个群多个项目点下单 | G17: OK-0625 | H17: OK-0701 | I17: ==_xlfn.XLOOKUP(B17,工作表2!A:A,工作表2!B:B) -> wrigAJEAAAEtJGi9pK0AJyh92DOGwpJw
A18: 17 | B18: 冀三姐下单群 | C18: 西安/丰厨(上海)供应链管理有限公司 | D18: KHXMD1823 | E18: 益海-遇见SPA（高新路店） | F18: 一个群多个项目点下单 | G18: OK-0625 | H18: OK-0701 | I18: ==_xlfn.XLOOKUP(B18,工作表2!A:A,工作表2!B:B) -> wrigAJEAAAEtJGi9pK0AJyh92DOGwpJw
A19: 18 | B19: 冀三姐下单群 | C19: 西安/丰厨(上海)供应链管理有限公司 | D19: KHXMD1825 | E19: 益海-悦竹SPA(海荣豪佳花园店) | F19: 一个群多个项目点下单 | G19: OK-0625 | H19: OK-0701 | I19: ==_xlfn.XLOOKUP(B19,工作表2!A:A,工作表2!B:B) -> wrigAJEAAAEtJGi9pK0AJyh92DOGwpJw
A20: 19 | B20: 冀三姐下单群 | C20: 西安/丰厨(上海)供应链管理有限公司 | D20: KHXMD1827 | E20: 益海-如遇SPA（凤城六路店） | F20: 一个群多个项目点下单 | G20: OK-0625 | H20: OK-0701 | I20: ==_xlfn.XLOOKUP(B20,工作表2!A:A,工作表2!B:B) -> wrigAJEAAAEtJGi9pK0AJyh92DOGwpJw
A21: 20 | B21: 冀三姐下单群 | C21: 西安/丰厨(上海)供应链管理有限公司 | D21: KHXMD1829 | E21: 益海-意品足浴(海璟蓝寓店) | F21: 一个群多个项目点下单 | G21: OK-0625 | H21: OK-0701 | I21: ==_xlfn.XLOOKUP(B21,工作表2!A:A,工作表2!B:B) -> wrigAJEAAAEtJGi9pK0AJyh92DOGwpJw
A22: 21 | B22: 冀三姐下单群 | C22: 西安/丰厨(上海)供应链管理有限公司 | D22: KHXMD1831 | E22: 益海-云端沐足（凤城五路） | F22: 一个群多个项目点下单 | G22: OK-0625 | H22: OK-0701 | I22: ==_xlfn.XLOOKUP(B22,工作表2!A:A,工作表2!B:B) -> wrigAJEAAAEtJGi9pK0AJyh92DOGwpJw
A23: 22 | B23: 丰厨-强华学校客户下单群 | C23: 西安/丰厨(上海)供应链管理有限公司 | D23: KHXMD2371 | E23: 陕西科技大学强华学校 | G23: OK-0625 | H23: OK | I23: ==_xlfn.XLOOKUP(B23,工作表2!A:A,工作表2!B:B) -> wrigAJEAAA7Bel4G031c11PoW0PB74vA
A24: 23 | B24: 丰厨_顺天府工作群 | C24: 北京/丰厨(上海)供应链管理有限公司 | D24: KHXMD5034 | E24: 顺天府 | G24: OK-0625 | H24: OK | I24: ==_xlfn.XLOOKUP(B24,工作表2!A:A,工作表2!B:B) -> wrigAJEAAAc-MieOJ_VVE-NKzT2BQkzA
A25: 24 | B25: 丰厨&亲和源内部沟通群 | C25: 上海/丰厨(上海)供应链管理有限公司 | D25: KHXMD4276 | E25: 亲和源 | G25: OK-0625 | H25: OK | I25: ==_xlfn.XLOOKUP(B25,工作表2!A:A,工作表2!B:B) -> wrigAJEAAA66nO815fxLSbJbm4scVnag
A26: 25 | B26: 同济大学内部沟通群 | C26: 上海/丰厨(上海)供应链管理有限公司 | D26: KHXMD3998 | E26: 同济大学 | G26: OK-0625 | H26: OK | I26: ==_xlfn.XLOOKUP(B26,工作表2!A:A,工作表2!B:B) -> wrigAJEAAAEl6xt3_cT0cKx6HseW4h7A
A27: 26 | B27: 中兴-丰厨沟通群 | C27: 上海/丰厨(上海)供应链管理有限公司 | D27: KHXMD09724 | E27: 中兴 | G27: OK-0625 | H27: OK | I27: ==_xlfn.XLOOKUP(B27,工作表2!A:A,工作表2!B:B) -> wrigAJEAAANkW08gwjVjZwD8vXc8PG4A
A28: 27 | B28: 神农氏内部沟通群 | C28: 上海/丰厨(上海)供应链管理有限公司 | D28: KHXMD4589 | E28: 神农氏-森兰国际 | F28: 一个群多个项目点下单 | G28: OK-0625 | H28: OK-0701 | I28: ==_xlfn.XLOOKUP(B28,工作表2!A:A,工作表2!B:B) -> wrigAJEAAAOsnYFLLKWTfHUQlX-GQ87A
A29: 28 | B29: 神农氏内部沟通群 | C29: 上海/丰厨(上海)供应链管理有限公司 | D29: KHXMD2687 | E29: 神农氏 | F29: 一个群多个项目点下单 | G29: OK-0625 | H29: OK-0701 | I29: ==_xlfn.XLOOKUP(B29,工作表2!A:A,工作表2!B:B) -> wrigAJEAAAOsnYFLLKWTfHUQlX-GQ87A
A30: 29 | B30: 朗富&丰厨供应链沟通群（金龙鱼） | C30: 上海/丰厨(上海)供应链管理有限公司 | D30: KHXMD0321 | E30: 上海朗富 | G30: OK-0625 | H30: OK | I30: ==_xlfn.XLOOKUP(B30,工作表2!A:A,工作表2!B:B) -> wrigAJEAAAUhuJIfux6yVlBNcOdM4H8Q
A31: 30 | B31: 德立安&星茉下单群 | C31: 益海嘉里德立安(陕西)食品有限公司 | D31: KHXMD09449 | E31: 西安星茉餐饮管理有限公司 | G31: OK-0625 | H31: OK | I31: ==_xlfn.XLOOKUP(B31,工作表2!A:A,工作表2!B:B) -> wrigAJEAAA3lK3LTgBjR95c3CgOYxl6w
A32: 31 | B32: 葡国餐厅对账接单群 | C32: 益海嘉里德立安(陕西)食品有限公司 | D32: BIZ20191231110214 | E32: 西安圣路易葡国餐饮有限公司 | G32: OK-0626 | H32: OK-0701 | I32: ==_xlfn.XLOOKUP(B32,工作表2!A:A,工作表2!B:B) -> wrigAJEAAARXlFY1n6xfQtUF7kIjuuYw
A33: 32 | B33: 益海-工厂买菜私聊 | C33: 郑州/丰厨(上海)供应链管理有限公司 | D33: KHXMD1615 | E33: 郑州工厂食堂 | G33: OK-0626 | H33: OK-0701 | I33: ==_xlfn.XLOOKUP(B33,工作表2!A:A,工作表2!B:B) -> wrigAJEAAAZERO5PQcgQVEzdkR-PB48w
A34: 33 | B34: 周口天天向上-丰厨供应链沟通群 | C34: 郑州/丰厨(上海)供应链管理有限公司 | D34: KHXMD5022 | E34: 天天向上 | G34: OK-0626 | H34: OK-0701 | I34: ==_xlfn.XLOOKUP(B34,工作表2!A:A,工作表2!B:B) -> wrigAJEAAAmaq9djC2cm72Ykvxcdi56w
A35: 34 | B35: 益海&全季郑汴路供应对接群 | C35: 郑州/丰厨(上海)供应链管理有限公司 | D35: KHXMD4984 | E35: 全季酒店 | G35: OK-0626 | H35: OK-0701 | I35: ==_xlfn.XLOOKUP(B35,工作表2!A:A,工作表2!B:B) -> wrigAJEAAAIaOcKnHS_n8Sng7o0i8lAg
A36: 35 | B36: 索迪斯内部沟通群 | C36: 益海嘉里食品营销有限公司上海分公司 | D36: KHXMD0210 | E36: 索迪斯 | G36: OK-0626 | H36: OK-0701 | I36: ==_xlfn.XLOOKUP(B36,工作表2!A:A,工作表2!B:B) -> wrigAJEAAAu9_6Tqyhvzj7YB6Oth-gzw
A37: 36 | B37: 丰厨_农科院工作群 | C37: 北京/丰厨(上海)供应链管理有限公司 | D37: KHXMD8797 | E37: 北京农科院 | G37: OK-0626 | H37: OK-0701 | I37: ==_xlfn.XLOOKUP(B37,工作表2!A:A,工作表2!B:B) -> wrigAJEAAAiUPBtOh1yVfxk2uT_l9RLA
A38: 37 | B38: 德立安-乐班下单群 | C38: 益海嘉里德立安(陕西)食品有限公司 | D38: KHXMD09894 | E38: 航天产业基地 | F38: 一个群多个项目点下单，需要修改项目点 | G38: OK-0626 | H38: OK-0701 | I38: ==_xlfn.XLOOKUP(B38,工作表2!A:A,工作表2!B:B) -> wrigAJEAAAvHVJBdRndOQSaF8EVW1Bjg
A39: 38 | B39: 德立安-乐班下单群 | C39: 益海嘉里德立安(陕西)食品有限公司 | D39: KHXMD10179 | E39: 航天产业基地-冷链配送 | F39: 一个群多个项目点下单，需要修改项目点 | G39: OK-0626 | H39: OK-0701 | I39: ==_xlfn.XLOOKUP(B39,工作表2!A:A,工作表2!B:B) -> wrigAJEAAAvHVJBdRndOQSaF8EVW1Bjg
A40: 39 | B40: 德立安&宝鸡海棠下单群 | C40: 益海嘉里德立安(陕西)食品有限公司 | D40: BIZ20181211152507 | E40: 宝鸡海棠酒店有限公司海棠假日酒店 | G40: OK-0626 | H40: OK-0701 | I40: ==_xlfn.XLOOKUP(B40,工作表2!A:A,工作表2!B:B) -> wrigAJEAAA2ea5gJKgJ4UGI7MMANkOCw
...

Sheet 工作表2
A1: 益分销PLUS-深圳国际会展中心洲际酒店 | B1: wrigAJEAAAFuEvg1ObWhcmy2q_M6Wq3g | C1: 邓虎 | D1: AI_QUAN，DMS_PLUS
A2: 德立安～太子湾逸菲下单群 | B2: wrigAJEAAADTfUfEE9mk0HLoKlK_PSfw | C2: 邓虎 | D2: AI_QUAN，DMS_PLUS
A3: 海谯汇-益海嘉里（丰厨） | B3: wrigAJEAAAbgyZq1soc1RQFfTj-hKASg | C3: 邓虎 | D3: AI_QUAN，DMS_PLUS
A4: 益海深度合作推进群 | B4: wrigAJEAAAouZAnW_S8Ep_O8DHKzadDA | C4: 邓虎 | D4: AI_QUAN，DMS_PLUS
A5: 杭州工厂-丰厨供应链业务对接群 | B5: wrigAJEAAAVSKtIQLmQz6mPCgLHHiFFw | C5: 邓虎 | D5: AI_QUAN，DMS_PLUS
A6: 德立安-辉胜阁订单群 | B6: wrigAJEAAATmrWPjznHCmzprmkomUE6Q | C6: 邓虎 | D6: AI_QUAN，DMS_PLUS
A7: 德立安-富悦订单群 | B7: wrigAJEAAA36ZXYMgR51AmStwcCel6qA | C7: 邓虎 | D7: AI_QUAN，DMS_PLUS
A8: 德立安-温德姆酒店下单群 | B8: wrigAJEAAAXnRYN0xEAjkHJNDM7rVfyA | C8: 邓虎 | D8: AI_QUAN，DMS_PLUS
A9: 德立安-悦来下单群 | B9: wrigAJEAAA0lzFlH6VPwiKciUNqEMvOA | C9: 邓虎 | D9: AI_QUAN，DMS_PLUS
A10: 丰厨-强华学校客户下单群 | B10: wrigAJEAAA7Bel4G031c11PoW0PB74vA | C10: 邓虎 | D10: AI_QUAN，DMS_PLUS
A11: 朗富供应链内部沟通群 | B11: wrigAJEAAAxDUNa6sagRNhNOl5JWZ-NQ | C11: 邓虎 | D11: AI_QUAN，DMS_PLUS
A12: 葡国餐厅对账接单群 | B12: wrigAJEAAARXlFY1n6xfQtUF7kIjuuYw | C12: 邓虎 | D12: AI_QUAN，DMS_PLUS
... A40: 工行&丰厨沟通群 | B40: wrigAJEAAAe2NsHQAkhgbX1oY65LY8xw | C40: 陈红姣 | D40: AI_QUAN，DMS_PLUS
A41: 人寿堂供应链业务对接群 | B41: wrigAJEAAATFcoRR62rWM94GBObBMHow
A42: 益海-中商（罗森）蔬菜供应沟通群 | B42: wrigAJEAAAfTP_LqvNuBeYhocgtfaF3A
A43: 粮贝铁路生鲜订单群 | B43: wrigAJEAAA4KoktJG0sUPh2pEDYtu0rA
A44: 铁路标品转单群 | B44: wrigAJEAAAmIHTBGttLsnui1xFR8fhww
A45: 安徽分-供应链oem产品对接 | B45: wrigAJEAAAsQDH7vvfDWPYx1L5jmK_cw
A46: 北京分-供应链oem产品对接 | B46: wrigAJEAAAPQOqlifrPl26osUSKUnk8w
A47: 成都分-供应链oem产品对接 | B47: wrigAJEAAAKCxIn_-2sZDlfuasu-gD-Q
A48: 重庆分-供应链oem产品对接 | B48: wrigAJEAAAwMSUF1QBg0ZEsaTQ7ESUPA
A49: 广州分-供应链oem产品对接 | B49: wrigAJEAAAzKomh6AAsTaCOrIYyfSvXg
A50: 贵阳分-供应链oem产品对接 | B50: wrigAJEAAAVjkkMfD2ILTcfgZ_tGlEZw
A51: 哈尔滨&长春分-供应链oem产品对接 | B51: wrigAJEAAAkN6-z9R_VbDMWTjWlIhz9w
A52: 济南分-供应链oem产品对接 | B52: wrigAJEAAALlVkCeZHC_mJ7U4KiDnDkg
... A72: 郑州&周口分-供应链oem产品对接 | B72: wrigAJEAAA0xta7ycDf5wxVzKW61afUQ
