Workbook
Name notifyRange: '工作表1'!$F$273

Sheet 工作表1
A1: 序号 | B1: 城市 | C1: 运营公司 | D1: 企业微信群名称 | E1: 项目点代码 | F1: 项目点名称 | G1: 备注 | H1: 创建人 | I1: 是否加群-张利拉 | J1: IT是否配置完成-邓虎 | K1: 群ID
A2: 1 | B2: 深圳 | C2: 深圳市德立安食品有限公司 | D2: 德立安～太子湾逸菲下单群 | E2: BIZ20240710105439 | F2: 深圳市裕顺达酒店管理有限公司 | I2: OK-0625 | J2: OK | K2: ==_xlfn.XLOOKUP(D2,工作表2!A:A,工作表2!B:B) -> #N/A
A3: 2 | B3: 浙江 | C3: 浙江/丰厨(上海)供应链管理有限公司 | D3: 商旅-武林之星项目业务对接群 | E3: KHXMD1152 | F3: 商旅-干调 | G3: 一个群多个项目点下单 | I3: OK-0625 | J3: OK-0701 | K3: ==_xlfn.XLOOKUP(D3,工作表2!A:A,工作表2!B:B) -> wrigAJEAAA6WrJotbzMQ1SlwWqkoWykg | L3: 删除
A4: 3 | B4: 浙江 | C4: 浙江/丰厨(上海)供应链管理有限公司 | D4: 商旅-武林之星项目业务对接群 | E4: KHXMD1076 | F4: 杭州商旅进出口贸易有限公司 | G4: 一个群多个项目点下单 | I4: OK-0625 | J4: OK-0701 | K4: ==_xlfn.XLOOKUP(D4,工作表2!A:A,工作表2!B:B) -> wrigAJEAAA6WrJotbzMQ1SlwWqkoWykg | L4: 删除
A5: 4 | B5: 浙江 | C5: 浙江/丰厨(上海)供应链管理有限公司 | D5: 海谯汇-益海嘉里（丰厨） | E5: KHXMD4918 | F5: 亳州海谯汇后勤管理服务有限公司 | I5: OK-0625 | J5: OK | K5: ==_xlfn.XLOOKUP(D5,工作表2!A:A,工作表2!B:B) -> #N/A | L5: 删除
A6: 5 | B6: 浙江 | C6: 浙江/丰厨(上海)供应链管理有限公司 | D6: 益海深度合作推进群 | E6: KHXMD9425 | F6: 浙江智汇配送有限公司利辛分公司 | I6: OK-0625 | J6: OK | K6: ==_xlfn.XLOOKUP(D6,工作表2!A:A,工作表2!B:B) -> #N/A | L6: 删除
A7: 6 | B7: 浙江 | C7: 浙江/丰厨(上海)供应链管理有限公司 | D7: 杭州工厂-丰厨供应链业务对接群 | E7: KHXMD0941 | F7: ZH-SP-ZLAQZN 益嘉工业-工厂食堂 | I7: OK-0625 | J7: OK | K7: ==_xlfn.XLOOKUP(D7,工作表2!A:A,工作表2!B:B) -> wrigAJEAAAVSKtIQLmQz6mPCgLHHiFFw | L7: 删除
A8: 7 | B8: 浙江 | C8: 浙江/丰厨(上海)供应链管理有限公司 | D8: 杭州央厨-供应链业务对接群 | E8: KHXMD2477 | F8: 益嘉丰厨-干调 | G8: 一个群多个项目点下单 | I8: OK-0625 | J8: OK-0701 | K8: ==_xlfn.XLOOKUP(D8,工作表2!A:A,工作表2!B:B) -> wrigAJEAAAmwtbpxOuj9iCIeu2tq4vEA | L8: 删除
A9: 8 | B9: 浙江 | C9: 浙江/丰厨(上海)供应链管理有限公司 | D9: 杭州央厨-供应链业务对接群 | E9: KHXMD1565 | F9: 杭州央厨-冻品 | G9: 一个群多个项目点下单 | I9: OK-0625 | J9: OK-0701 | K9: ==_xlfn.XLOOKUP(D9,工作表2!A:A,工作表2!B:B) -> wrigAJEAAAmwtbpxOuj9iCIeu2tq4vEA | L9: 删除
A10: 9 | B10: 浙江 | C10: 浙江/丰厨(上海)供应链管理有限公司 | D10: 杭州央厨-供应链业务对接群 | E10: KHXMD0243 | F10: 益嘉丰厨（杭州）食品有限公司 | G10: 一个群多个项目点下单 | I10: OK-0625 | J10: OK-0701 | K10: ==_xlfn.XLOOKUP(D10,工作表2!A:A,工作表2!B:B) -> wrigAJEAAAmwtbpxOuj9iCIeu2tq4vEA | L10: 删除
A11: 10 | B11: 深圳 | C11: 深圳市德立安食品有限公司 | D11: 益分销PLUS-深圳国际会展中心洲际酒店 | E11: BIZ20230510111217 | F11: 深圳市招华国际会展发展有限公司深圳国际会展中心洲际酒店 -会展湾中港广场6栋A座 | I11: OK-0625 | J11: OK | K11: ==_xlfn.XLOOKUP(D11,工作表2!A:A,工作表2!B:B) -> #N/A
A12: 11 | B12: 深圳 | C12: 深圳市德立安食品有限公司 | D12: 德立安-辉胜阁订单群 | E12: BIZ20240814142654 | F12: 深圳市中航城置业发展有限公司辉盛阁国际公寓分公司 | I12: OK-0625 | J12: OK | K12: ==_xlfn.XLOOKUP(D12,工作表2!A:A,工作表2!B:B) -> wrigAJEAAATmrWPjznHCmzprmkomUE6Q
A13: 12 | B13: 深圳 | C13: 深圳市德立安食品有限公司 | D13: 德立安-富悦订单群 | E13: BIZ20250605134442 | F13: 富悦(深圳)酒店管理有限公司 | I13: OK-0625 | J13: OK | K13: ==_xlfn.XLOOKUP(D13,工作表2!A:A,工作表2!B:B) -> wrigAJEAAA36ZXYMgR51AmStwcCel6qA
A14: 13 | B14: 西安 | C14: 益海嘉里德立安(陕西)食品有限公司 | D14: 德立安-温德姆酒店下单群 | E14: BIZ20240511112021 | F14: 西安豪享来投资控股有限公司豪享来温德姆至尊酒店 | I14: OK-0625 | J14: OK | K14: ==_xlfn.XLOOKUP(D14,工作表2!A:A,工作表2!B:B) -> wrigAJEAAAXnRYN0xEAjkHJNDM7rVfyA
A15: 14 | B15: 西安 | C15: 益海嘉里德立安(陕西)食品有限公司 | D15: 德立安-悦来下单群 | E15: BIZ20230506163709 | F15: 西安悦来酒店管理有限公司曲江新区分公司 | I15: OK-0625 | J15: OK | K15: ==_xlfn.XLOOKUP(D15,工作表2!A:A,工作表2!B:B) -> wrigAJEAAA0lzFlH6VPwiKciUNqEMvOA
A16: 15 | B16: 西安 | C16: 西安/丰厨(上海)供应链管理有限公司 | D16: 冀三姐下单群 | E16: KHXMD1819 | F16: 益海-大寨路天悦店 | G16: 一个群多个项目点下单 | I16: OK-0625 | J16: OK-0701 | K16: ==_xlfn.XLOOKUP(D16,工作表2!A:A,工作表2!B:B) -> wrigAJEAAAEtJGi9pK0AJyh92DOGwpJw
A17: 16 | B17: 西安 | C17: 西安/丰厨(上海)供应链管理有限公司 | D17: 冀三姐下单群 | E17: KHXMD1820 | F17: 益海-财富中心店 | G17: 一个群多个项目点下单 | I17: OK-0625 | J17: OK-0701 | K17: ==_xlfn.XLOOKUP(D17,工作表2!A:A,工作表2!B:B) -> wrigAJEAAAEtJGi9pK0AJyh92DOGwpJw
A18: 17 | B18: 西安 | C18: 西安/丰厨(上海)供应链管理有限公司 | D18: 冀三姐下单群 | E18: KHXMD1823 | F18: 益海-遇见SPA（高新路店） | G18: 一个群多个项目点下单 | I18: OK-0625 | J18: OK-0701 | K18: ==_xlfn.XLOOKUP(D18,工作表2!A:A,工作表2!B:B) -> wrigAJEAAAEtJGi9pK0AJyh92DOGwpJw
A19: 18 | B19: 西安 | C19: 西安/丰厨(上海)供应链管理有限公司 | D19: 冀三姐下单群 | E19: KHXMD1825 | F19: 益海-悦竹SPA(海荣豪佳花园店) | G19: 一个群多个项目点下单 | I19: OK-0625 | J19: OK-0701 | K19: ==_xlfn.XLOOKUP(D19,工作表2!A:A,工作表2!B:B) -> wrigAJEAAAEtJGi9pK0AJyh92DOGwpJw
A20: 19 | B20: 西安 | C20: 西安/丰厨(上海)供应链管理有限公司 | D20: 冀三姐下单群 | E20: KHXMD1827 | F20: 益海-如遇SPA（凤城六路店） | G20: 一个群多个项目点下单 | I20: OK-0625 | J20: OK-0701 | K20: ==_xlfn.XLOOKUP(D20,工作表2!A:A,工作表2!B:B) -> wrigAJEAAAEtJGi9pK0AJyh92DOGwpJw
A21: 20 | B21: 西安 | C21: 西安/丰厨(上海)供应链管理有限公司 | D21: 冀三姐下单群 | E21: KHXMD1829 | F21: 益海-意品足浴(海璟蓝寓店) | G21: 一个群多个项目点下单 | I21: OK-0625 | J21: OK-0701 | K21: ==_xlfn.XLOOKUP(D21,工作表2!A:A,工作表2!B:B) -> wrigAJEAAAEtJGi9pK0AJyh92DOGwpJw
A22: 21 | B22: 西安 | C22: 西安/丰厨(上海)供应链管理有限公司 | D22: 冀三姐下单群 | E22: KHXMD1831 | F22: 益海-云端沐足（凤城五路） | G22: 一个群多个项目点下单 | I22: OK-0625 | J22: OK-0701 | K22: ==_xlfn.XLOOKUP(D22,工作表2!A:A,工作表2!B:B) -> wrigAJEAAAEtJGi9pK0AJyh92DOGwpJw
A23: 22 | B23: 西安 | C23: 西安/丰厨(上海)供应链管理有限公司 | D23: 丰厨-强华学校客户下单群 | E23: KHXMD2371 | F23: 陕西科技大学强华学校 | I23: OK-0625 | J23: OK | K23: ==_xlfn.XLOOKUP(D23,工作表2!A:A,工作表2!B:B) -> wrigAJEAAA7Bel4G031c11PoW0PB74vA
A24: 23 | B24: 北京 | C24: 北京/丰厨(上海)供应链管理有限公司 | D24: 丰厨_顺天府工作群 | E24: KHXMD5034 | F24: 顺天府 | I24: OK-0625 | J24: OK | K24: ==_xlfn.XLOOKUP(D24,工作表2!A:A,工作表2!B:B) -> wrigAJEAAAc-MieOJ_VVE-NKzT2BQkzA
A25: 24 | B25: 西安 | C25: 西安/丰厨(上海)供应链管理有限公司 | D25: 丰厨&亲和源内部沟通群 | E25: KHXMD4276 | F25: 亲和源 | I25: OK-0625 | J25: OK | K25: ==_xlfn.XLOOKUP(D25,工作表2!A:A,工作表2!B:B) -> wrigAJEAAA66nO815fxLSbJbm4scVnag
A26: 25 | B26: 上海 | C26: 上海/丰厨(上海)供应链管理有限公司 | D26: 同济大学内部沟通群 | E26: KHXMD3998 | F26: 同济大学 | I26: OK-0625 | J26: OK | K26: ==_xlfn.XLOOKUP(D26,工作表2!A:A,工作表2!B:B) -> wrigAJEAAAEl6xt3_cT0cKx6HseW4h7A
A27: 26 | B27: 上海 | C27: 上海/丰厨(上海)供应链管理有限公司 | D27: 中兴-丰厨沟通群 | E27: KHXMD09724 | F27: 中兴 | I27: OK-0625 | J27: OK | K27: ==_xlfn.XLOOKUP(D27,工作表2!A:A,工作表2!B:B) -> wrigAJEAAANkW08gwjVjZwD8vXc8PG4A
A28: 27 | B28: 上海 | C28: 上海/丰厨(上海)供应链管理有限公司 | D28: 神农氏内部沟通群 | E28: KHXMD4589 | F28: 神农氏-森兰国际 | G28: 一个群多个项目点下单 | I28: OK-0625 | J28: OK-0701 | K28: ==_xlfn.XLOOKUP(D28,工作表2!A:A,工作表2!B:B) -> wrigAJEAAAOsnYFLLKWTfHUQlX-GQ87A
A29: 28 | B29: 上海 | C29: 上海/丰厨(上海)供应链管理有限公司 | D29: 神农氏内部沟通群 | E29: KHXMD2687 | F29: 神农氏 | G29: 一个群多个项目点下单 | I29: OK-0625 | J29: OK-0701 | K29: ==_xlfn.XLOOKUP(D29,工作表2!A:A,工作表2!B:B) -> wrigAJEAAAOsnYFLLKWTfHUQlX-GQ87A
A30: 29 | B30: 上海 | C30: 上海/丰厨(上海)供应链管理有限公司 | D30: 朗富&丰厨供应链沟通群（金龙鱼） | E30: KHXMD0321 | F30: 上海朗富 | I30: OK-0625 | J30: OK | K30: ==_xlfn.XLOOKUP(D30,工作表2!A:A,工作表2!B:B) -> wrigAJEAAAUhuJIfux6yVlBNcOdM4H8Q
A31: 30 | B31: 西安 | C31: 益海嘉里德立安(陕西)食品有限公司 | D31: 德立安&星茉下单群 | E31: KHXMD09449 | F31: 西安星茉餐饮管理有限公司 | I31: OK-0625 | J31: OK | K31: ==_xlfn.XLOOKUP(D31,工作表2!A:A,工作表2!B:B) -> wrigAJEAAA3lK3LTgBjR95c3CgOYxl6w
A32: 31 | B32: 西安 | C32: 益海嘉里德立安(陕西)食品有限公司 | D32: 葡国餐厅对账接单群 | E32: BIZ20191231110214 | F32: 西安圣路易葡国餐饮有限公司 | I32: OK-0626 | J32: OK-0701 | K32: ==_xlfn.XLOOKUP(D32,工作表2!A:A,工作表2!B:B) -> wrigAJEAAARXlFY1n6xfQtUF7kIjuuYw
A33: 32 | B33: 郑州 | C33: 郑州/丰厨(上海)供应链管理有限公司 | D33: 益海-工厂买菜私聊 | E33: KHXMD1615 | F33: 郑州工厂食堂 | I33: OK-0626 | J33: OK-0701 | K33: ==_xlfn.XLOOKUP(D33,工作表2!A:A,工作表2!B:B) -> wrigAJEAAAZERO5PQcgQVEzdkR-PB48w
A34: 33 | B34: 郑州 | C34: 郑州/丰厨(上海)供应链管理有限公司 | D34: 周口天天向上-丰厨供应链沟通群 | E34: KHXMD5022 | F34: 天天向上 | I34: OK-0626 | J34: OK-0701 | K34: ==_xlfn.XLOOKUP(D34,工作表2!A:A,工作表2!B:B) -> wrigAJEAAAmaq9djC2cm72Ykvxcdi56w
A35: 34 | B35: 郑州 | C35: 郑州/丰厨(上海)供应链管理有限公司 | D35: 益海&全季郑汴路供应对接群 | E35: KHXMD4984 | F35: 全季酒店 | I35: OK-0626 | J35: OK-0701 | K35: ==_xlfn.XLOOKUP(D35,工作表2!A:A,工作表2!B:B) -> wrigAJEAAAIaOcKnHS_n8Sng7o0i8lAg
A36: 35 | B36: 上海 | C36: 益海嘉里食品营销有限公司上海分公司 | D36: 索迪斯内部沟通群 | E36: KHXMD0210 | F36: 索迪斯 | I36: OK-0626 | J36: OK-0701 | K36: ==_xlfn.XLOOKUP(D36,工作表2!A:A,工作表2!B:B) -> wrigAJEAAAu9_6Tqyhvzj7YB6Oth-gzw
A37: 36 | B37: 北京 | C37: 北京/丰厨(上海)供应链管理有限公司 | D37: 丰厨_农科院工作群 | E37: KHXMD8797 | F37: 北京农科院 | I37: OK-0626 | J37: OK-0701 | K37: ==_xlfn.XLOOKUP(D37,工作表2!A:A,工作表2!B:B) -> wrigAJEAAAiUPBtOh1yVfxk2uT_l9RLA
A38: 37 | B38: 西安 | C38: 益海嘉里德立安(陕西)食品有限公司 | D38: 德立安-乐班下单群 | E38: KHXMD09894 | F38: 航天产业基地 | G38: 一个群多个项目点下单，需要修改项目点 | I38: OK-0626 | J38: OK-0701 | K38: ==_xlfn.XLOOKUP(D38,工作表2!A:A,工作表2!B:B) -> wrigAJEAAAvHVJBdRndOQSaF8EVW1Bjg
A39: 38 | B39: 西安 | C39: 益海嘉里德立安(陕西)食品有限公司 | D39: 德立安-乐班下单群 | E39: KHXMD10179 | F39: 航天产业基地-冷链配送 | G39: 一个群多个项目点下单，需要修改项目点 | I39: OK-0626 | J39: OK-0701 | K39: ==_xlfn.XLOOKUP(D39,工作表2!A:A,工作表2!B:B) -> wrigAJEAAAvHVJBdRndOQSaF8EVW1Bjg
A40: 39 | B40: 西安 | C40: 益海嘉里德立安(陕西)食品有限公司 | D40: 德立安&宝鸡海棠下单群 | E40: BIZ20181211152507 | F40: 宝鸡海棠酒店有限公司海棠假日酒店 | I40: OK-0626 | J40: OK-0701 | K40: ==_xlfn.XLOOKUP(D40,工作表2!A:A,工作表2!B:B) -> wrigAJEAAA2ea5gJKgJ4UGI7MMANkOCw
...

Sheet 工作表2
A1: 天津瑞吉酒店 德立安服务群 | B1: wrigAJEAAA0G1K8Vh1Aktlwxpe0WsSoQ | C1: 邓虎 | D1: AI_QUAN，DMS_PLUS
A2: 浙江丰厨运营AI转单群 | B2: wrigAJEAAAxNcmzy8tO9p9MJ18nr-sLg | C2: 邓虎 | D2: AI_QUAN，DMS_PLUS
A3: 德立安&米屋下单群 | B3: wrigAJEAAAjKZssLHb8pmlg2-Zpvv5yw | C3: 邓虎 | D3: AI_QUAN，DMS_PLUS
A4: 德立安陕西-栀初-如意茵香茂御酒店下单 | B4: wrigAJEAAANRvyCCA5xtayf-dJ0W6AAg | C4: 邓虎 | D4: AI_QUAN，DMS_PLUS
A5: 杭州工厂-丰厨供应链业务对接群 | B5: wrigAJEAAAVSKtIQLmQz6mPCgLHHiFFw | C5: 邓虎 | D5: AI_QUAN，DMS_PLUS
A6: 德立安-辉胜阁订单群 | B6: wrigAJEAAATmrWPjznHCmzprmkomUE6Q | C6: 邓虎 | D6: AI_QUAN，DMS_PLUS
A7: 德立安-富悦订单群 | B7: wrigAJEAAA36ZXYMgR51AmStwcCel6qA | C7: 邓虎 | D7: AI_QUAN，DMS_PLUS
A8: 德立安-温德姆酒店下单群 | B8: wrigAJEAAAXnRYN0xEAjkHJNDM7rVfyA | C8: 邓虎 | D8: AI_QUAN，DMS_PLUS
A9: 德立安-悦来下单群 | B9: wrigAJEAAA0lzFlH6VPwiKciUNqEMvOA | C9: 邓虎 | D9: AI_QUAN，DMS_PLUS
A10: 丰厨-强华学校客户下单群 | B10: wrigAJEAAA7Bel4G031c11PoW0PB74vA | C10: 邓虎 | D10: AI_QUAN，DMS_PLUS
A11: 朗富供应链内部沟通群 | B11: wrigAJEAAAxDUNa6sagRNhNOl5JWZ-NQ | C11: 邓虎 | D11: AI_QUAN，DMS_PLUS
A12: 葡国餐厅对账接单群 | B12: wrigAJEAAARXlFY1n6xfQtUF7kIjuuYw | C12: 邓虎 | D12: AI_QUAN，DMS_PLUS
... A40: 工行&丰厨沟通群 | B40: wrigAJEAAAe2NsHQAkhgbX1oY65LY8xw | C40: 陈红姣 | D40: AI_QUAN，DMS_PLUS
A41: 人寿堂供应链业务对接群 | B41: wrigAJEAAATFcoRR62rWM94GBObBMHow
A42: 益海-中商（罗森）蔬菜供应沟通群 | B42: wrigAJEAAAfTP_LqvNuBeYhocgtfaF3A
A43: 粮贝铁路生鲜订单群 | B43: wrigAJEAAA4KoktJG0sUPh2pEDYtu0rA
A44: 铁路标品转单群 | B44: wrigAJEAAAmIHTBGttLsnui1xFR8fhww
A45: 安徽分-供应链oem产品对接 | B45: wrigAJEAAAsQDH7vvfDWPYx1L5jmK_cw
A46: 北京分-供应链oem产品对接 | B46: wrigAJEAAAPQOqlifrPl26osUSKUnk8w
A47: 成都分-供应链oem产品对接 | B47: wrigAJEAAAKCxIn_-2sZDlfuasu-gD-Q
A48: 重庆分-供应链oem产品对接 | B48: wrigAJEAAAwMSUF1QBg0ZEsaTQ7ESUPA
A49: 广州分-供应链oem产品对接 | B49: wrigAJEAAAzKomh6AAsTaCOrIYyfSvXg
A50: 贵阳分-供应链oem产品对接 | B50: wrigAJEAAAVjkkMfD2ILTcfgZ_tGlEZw
A51: 哈尔滨&长春分-供应链oem产品对接 | B51: wrigAJEAAAkN6-z9R_VbDMWTjWlIhz9w
A52: 济南分-供应链oem产品对接 | B52: wrigAJEAAALlVkCeZHC_mJ7U4KiDnDkg
... A92: 中山华邑&逸衡采购沟通群（德立安） | B92: wrigAJEAAA1U_UdU5xMUawy-Y2J4Nmcw
